Workbook

Sheet تعليمات
B1: جدول تجميع استبيان أصحاب المحلات — منصة شارع الغالي
B3: كيف تُدخل استمارة؟
B4: 1. في ورقة «الإجابات» كل صف = استمارة واحدة. ابدأ من الصف 4. الصف 3 (الرمادي) مثال فقط ولا يدخل في الحسابات.
B5: 2. اكتب رقم الاستمارة في العمود الأول دائمًا؛ الصف بدون رقم استمارة لا يُحسب في «عدد الاستمارات».
B6: 3. أسئلة الاختيار الواحد: اختر الإجابة من القائمة المنسدلة (لا تكتبها بيدك).
B7: 4. أسئلة الاختيار المتعدد (س4، س5، س6، س9، س10، س22، س30، س40): اكتب 1 تحت كل خيار اختاره صاحب المحل، واترك الباقي فارغًا.
B8: 5. س35 (ترتيب المشاكل): اكتب 1 تحت أهم مشكلة، و2 تحت الثانية، و3 تحت الثالثة. اترك البقية فارغة.
B9: 6. س21 (نسب الدفع): اكتب أرقامًا فقط من 0 إلى 100، ويُفضّل أن يكون مجموعها 100.
B10: 7. س32 وس38: رقم من 1 إلى 5. س43: المبلغ بالجنيه رقمًا فقط (مثل 10000).
B11: 8. الأسئلة المفتوحة (س27، س34، س36، س37): انسخ كلام صاحب المحل كما كتبه الباحث، دون تلخيص.
B12: 9. إذا لم يُجب صاحب المحل عن سؤال، اترك الخانة فارغة.
B14: أين أجد النتائج؟
... B19: أعمدة «بيانات التواصل» فيها أرقام هواتف أشخاص. احفظ الملف في مكان آمن ولا ترسله إلا لفريق العمل.

Sheet الإجابات
A1: بيانات المقابلة | G1: س1. منذ متى يعمل المحل | H1: س2. صفة المجيب | I1: س3. عدد العاملين | J1: س4. ما يبيعه المحل | V1: س5. نوع القطع | Y1: س6. أنواع العربيات | AG1: س7. عدد الأصناف | AH1: س8. الزبائن في اليوم | AI1: س9. مصادر الزبائن | AO1: س10. كيف يسأل الزبون | AS1: س11. السؤال عن قطع غير موجودة | AT1: س12. عند عدم توفر القطعة | AU1: س13. زبون لا يعرف اسم القطعة | AW1: س14. وقت الرد على الأسئلة يوميًا | AX1: س15. التوصيل خارج الشارع | AY1: س16. تغيّر الأسعار | AZ1: س17. معرفة المخزون | BA1: س18. البيع بسعر قديم | BB1: س19. تحديد السعر | BC1: س20. ظهور الأسعار على الإنترنت | BE1: س21. نسب طرق الدفع (%) | BI1: س22. مشاكل تحويلات بنكك | BO1: س23. البيع بالدين | BP1: س24. طلب التركيب | BQ1: س25. من يركّب | BR1: س26. شكاوى «ما ركبت» | BS1: س27. التعامل مع الإرجاع | BT1: س28. الهاتف المستخدم | BU1: س29. شبكة الإنترنت | BV1: س30. التطبيقات المستخدمة | CB1: س31. البريد الإلكتروني | CC1: س32. الراحة مع التطبيقات (1–5) | CD1: س33. من سيستخدم التطبيق | CE1: س34. أكبر مشكلة (بكلامه) | CF1: س35. ترتيب أهم 3 مشاكل (1–3) | CS1: س36. الحاجة الواحدة التي يتمنى تغييرها | CT1: س37. تجربة سابقة مع تطبيق أو موقع | CU1: س38. الاهتمام بالفكرة (1–5) | CV1: س39. أهمية الميزات | DE1: س40. المخاوف | DM1: س41. طريقة الدفع المفضلة | DN1: س42. أعلى عمولة يقبلها | DO1: س43. أعلى اشتراك شهري يقبله (جنيه) | DP1: س44. يريد أن يكون من أول المحلات | DQ1: س45. يسمح بالتواصل لاحقًا | DR1: بيانات التواصل | DU1: ملاحظات الباحث
A2: رقم الاستمارة | B2: اسم الباحث | C2: التاريخ | D2: المنطقة / رقم المحل | E2: مدة المقابلة (دقائق) | F2: موافقة صاحب المحل | G2: الإجابة | H2: الإجابة | I2: الإجابة | J2: إضاءة ولمبات | K2: كهرباء وبطاريات | L2: تكييف | M2: عفشة وتعليق | N2: فرامل | O2: زيوت وفلاتر | P2: قطع ماكينة | Q2: صوت وشاشات | R2: إكسسوارات داخلية وخارجية | S2: إطارات وجنوط | T2: زجاج ومرايات | U2: أخرى (اكتبها) | V2: جديد أصلي (وكالة) | W2: جديد تجاري | X2: مستعمل (تشليح) | Y2: تويوتا | Z2: هيونداي | AA2: كيا | AB2: نيسان | AC2: ميتسوبيشي | AD2: إيسوزو | AE2: جميع الأنواع | AF2: أخرى (اكتبها) | AG2: الإجابة | AH2: الإجابة | AI2: زبائن قدامى معروفون | AJ2: مارّون في الشارع | AK2: بتوصية من معارف | AL2: ميكانيكيون وفنيون يحضرونهم | AM2: من فيسبوك أو واتساب | AN2: من خارج المدينة | AO2: يحضر بنفسه | AP2: مكالمة هاتفية | AQ2: رسالة أو صورة على واتساب | AR2: يرسل ميكانيكي أو مندوب | AS2: الإجابة | AT2: الإجابة | AU2: الإجابة | AV2: تفاصيل | AW2: الإجابة | AX2: الإجابة | AY2: الإجابة | AZ2: الإجابة | BA2: الإجابة | BB2: الإجابة | BC2: الإجابة | BD2: السبب | BE2: كاش % | BF2: بنكك % | BG2: تطبيق أو بنك آخر % | BH2: دين (آجل) % | BI2: إشعار مزوّر أو غير حقيقي | BJ2: تحويل تأخر وصوله | BK2: مبلغ ناقص | BL2: صعوبة التأكد من وصول التحويل | BM2: لم أواجه مشاكل | BN2: أخرى (اكتبها) | BO2: الإجابة | BP2: الإجابة | BQ2: الإجابة | BR2: الإجابة | BS2: الإجابة بكلامه | BT2: الإجابة | BU2: الإجابة | BV2: واتساب | BW2: فيسبوك | BX2: بنكك | BY2: تيك توك | BZ2: إكسل أو برنامج محاسبة | CA2: لا شيء | CB2: الإجابة | CC2: من 1 إلى 5 | CD2: الإجابة | CE2: الإجابة بكلامه | CF2: قلة الزبائن الجدد | CG2: زبائن يسألون عن قطع غير موجودة عندي | CH2: تغيّر الأسعار وصعوبة متابعتها | CI2: ضياع الوقت في الرد على الأسئلة بالهاتف | CJ2: معرفة المخزون والكميات | CK2: مشاكل الدفع والتحويلات | CL2: الدين وصعوبة التحصيل | CM2: إرجاع القطع والشكاوى | CN2: إيجاد فني موثوق للتركيب | CO2: المنافسة بين المحلات | CP2: الحصول على البضاعة من الموردين | CQ2: أخرى | CR2: أخرى: ما هي؟ | CS2: الإجابة بكلامه | CT2: الإجابة بكلامه | CU2: من 1 إلى 5 | CV2: زبائن جدد يجدون محلي بالبحث | CW2: طلبات تسعير بالصورة | CX2: تحديث الأسعار بسرعة | CY2: متابعة المخزون والكميات | CZ2: حجز فني لتركيب القطعة | DA2: التأكد من تحويلات بنكك | DB2: كشف حساب بالمبيعات والأرباح | DC2: حسابات للموظفين | DD2: توصيل القطع للزبائن | DE2: التكلفة | DF2: الثقة في وصول القروش | DG2: ظهور أسعاري للمنافسين | DH2: صعوبة الاستخدام | DI2: ضياع الوقت | DJ2: ضعف الإنترنت | DK2: لا شيء | DL2: أخرى (اكتبها) | DM2: الإجابة | DN2: الإجابة | DO2: المبلغ بالجنيه | DP2: الإجابة | DQ2: الإجابة | DR2: الاسم (اختياري) | DS2: الهاتف / واتساب (اختياري) | DT2: اسم المحل (اختياري) | DU2: حجم المحل | DV2: تنظيم المحل والبضاعة | DW2: راحة صاحب المحل مع الهاتف | DX2: مكانته وتأثيره | DY2: اهتمامه الحقيقي بالفكرة | DZ2: كان مستعجلًا أثناء المقابلة | EA2: أهم ما لفت الانتباه
A3: مثال | B3: أحمد | C3: 2026-10-20 | D3: المنطقة 2 / محل 14 | E3: 18 | F3: نعم | G3: 6–10 سنوات | H3: شريك | I3: أكثر من 5 | J3: 1 | K3: 1 | R3: 1 | W3: 1 | Y3: 1 | Z3: 1 | AC3: 1 | AG3: أقل من 100 | AH3: أقل من 5 | AI3: 1 | AL3: 1 | AO3: 1 | AS3: أغلب الزبائن | AT3: أعتذر ويذهب الزبون | AU3: يحضر القطعة القديمة | AV3: يرسل صورة على واتساب غالبًا | AW3: أقل من ساعة | AX3: نعم، بنفسي أو بموظف | AY3: نادرًا | AZ3: من ذاكرتي | BA3: أحيانًا | BB3: حسب سعر الشراء + ربح ثابت | BC3: أمانع جدًا | BD3: يرسل صورة على واتساب غالبًا | BE3: 50 | BF3: 30 | BG3: 0 | BH3: 20 | BI3: 1 | BJ3: 1 | BO3: أبيع وأجد صعوبة في التحصيل | BP3: أحيانًا | BQ3: فني في الشارع أتعامل معه | BR3: كثيرًا | BS3: مثال: الزبون يرجع القطعة إذا ما ركبت، وأخسر وقتي | BT3: هاتف عادي (غير ذكي) | BU3: ضعيفة جدًا | BV3: 1 | BW3: 1 | BX3: 1 | CB3: لا | CC3: 1 | CD3: موظف في المحل | CE3: مثال: الزبون يرجع القطعة إذا ما ركبت، وأخسر وقتي | CF3: 1 | CI3: 3 | CO3: 2 | CS3: مثال: الزبون يرجع القطعة إذا ما ركبت، وأخسر وقتي | CT3: مثال: الزبون يرجع القطعة إذا ما ركبت، وأخسر وقتي | CU3: 4 | CV3: غير مهمة | CW3: غير مهمة | CX3: مهمة | CY3: مهمة | CZ3: مهمة | DA3: غير مهمة | DB3: مهمة | DC3: مهمة | DD3: مهمة | DK3: 1 | DM3: اشتراك شهري ثابت | DN3: نسبة 3% | DO3: 15000 | DP3: لا | DQ3: لا | DR3: (اختياري) | DU3: متوسط | DV3: غير منظم | DW3: متوسطة | DX3: عادي | DY3: ضعيف | DZ3: نعم | EA3: مؤثر في المنطقة، مهتم جدًا بطلبات التسعير بالصورة

Sheet الملخص
A1: ملخص استبيان أصحاب المحلات
A2: كل الأرقام في هذه الورقة تُحسب تلقائيًا من ورقة «الإجابات». لا تكتب فيها.
A3: أهم النتائج
A4: عدد الاستمارات المُدخلة | B4: =COUNTA(الإجابات!$A$4:$A$303) -> 0
A5: متوسط مدة المقابلة (دقائق) | B5: =IFERROR(AVERAGE(الإجابات!$E$4:$E$303),"—") -> —
A6: أهم المشاكل (س35)
A7: النقاط: المرتبة الأولى = 3 نقاط، الثانية = 2، الثالثة = 1. «ذكرها» = عدد من رتّبها ضمن أهم 3.
A8: المشكلة | B8: النقاط | C8: ذكرها | D8: % من الاستمارات | E8: الترتيب
A9: قلة الزبائن الجدد | B9: =COUNTIF(الإجابات!$CF$4:$CF$303,1)*3+COUNTIF(الإجابات!$CF$4:$CF$303,2)*2+COUNTIF(الإجابات!$CF$4:$CF$303,3) -> 0 | C9: =COUNT(الإجابات!$CF$4:$CF$303) -> 0 | D9: =IFERROR(C9/$B$4,0) -> 0 | E9: =RANK(F9,$F$9:$F$20) -> 1 | F9: =B9+C9/1000+(12-0)/100000 -> 0.00012
A10: زبائن يسألون عن قطع غير موجودة عندي | B10: =COUNTIF(الإجابات!$CG$4:$CG$303,1)*3+COUNTIF(الإجابات!$CG$4:$CG$303,2)*2+COUNTIF(الإجابات!$CG$4:$CG$303,3) -> 0 | C10: =COUNT(الإجابات!$CG$4:$CG$303) -> 0 | D10: =IFERROR(C10/$B$4,0) -> 0 | E10: =RANK(F10,$F$9:$F$20) -> 2 | F10: =B10+C10/1000+(12-1)/100000 -> 0.00011
A11: تغيّر الأسعار وصعوبة متابعتها | B11: =COUNTIF(الإجابات!$CH$4:$CH$303,1)*3+COUNTIF(الإجابات!$CH$4:$CH$303,2)*2+COUNTIF(الإجابات!$CH$4:$CH$303,3) -> 0 | C11: =COUNT(الإجابات!$CH$4:$CH$303) -> 0 | D11: =IFERROR(C11/$B$4,0) -> 0 | E11: =RANK(F11,$F$9:$F$20) -> 3 | F11: =B11+C11/1000+(12-2)/100000 -> 0.0001
A12: ضياع الوقت في الرد على الأسئلة بالهاتف | B12: =COUNTIF(الإجابات!$CI$4:$CI$303,1)*3+COUNTIF(الإجابات!$CI$4:$CI$303,2)*2+COUNTIF(الإجابات!$CI$4:$CI$303,3) -> 0 | C12: =COUNT(الإجابات!$CI$4:$CI$303) -> 0 | D12: =IFERROR(C12/$B$4,0) -> 0 | E12: =RANK(F12,$F$9:$F$20) -> 4 | F12: =B12+C12/1000+(12-3)/100000 -> 9e-05
A13: معرفة المخزون والكميات | B13: =COUNTIF(الإجابات!$CJ$4:$CJ$303,1)*3+COUNTIF(الإجابات!$CJ$4:$CJ$303,2)*2+COUNTIF(الإجابات!$CJ$4:$CJ$303,3) -> 0 | C13: =COUNT(الإجابات!$CJ$4:$CJ$303) -> 0 | D13: =IFERROR(C13/$B$4,0) -> 0 | E13: =RANK(F13,$F$9:$F$20) -> 5 | F13: =B13+C13/1000+(12-4)/100000 -> 8e-05
A14: مشاكل الدفع والتحويلات | B14: =COUNTIF(الإجابات!$CK$4:$CK$303,1)*3+COUNTIF(الإجابات!$CK$4:$CK$303,2)*2+COUNTIF(الإجابات!$CK$4:$CK$303,3) -> 0 | C14: =COUNT(الإجابات!$CK$4:$CK$303) -> 0 | D14: =IFERROR(C14/$B$4,0) -> 0 | E14: =RANK(F14,$F$9:$F$20) -> 6 | F14: =B14+C14/1000+(12-5)/100000 -> 7e-05
A15: الدين وصعوبة التحصيل | B15: =COUNTIF(الإجابات!$CL$4:$CL$303,1)*3+COUNTIF(الإجابات!$CL$4:$CL$303,2)*2+COUNTIF(الإجابات!$CL$4:$CL$303,3) -> 0 | C15: =COUNT(الإجابات!$CL$4:$CL$303) -> 0 | D15: =IFERROR(C15/$B$4,0) -> 0 | E15: =RANK(F15,$F$9:$F$20) -> 7 | F15: =B15+C15/1000+(12-6)/100000 -> 6e-05
A16: إرجاع القطع والشكاوى | B16: =COUNTIF(الإجابات!$CM$4:$CM$303,1)*3+COUNTIF(الإجابات!$CM$4:$CM$303,2)*2+COUNTIF(الإجابات!$CM$4:$CM$303,3) -> 0 | C16: =COUNT(الإجابات!$CM$4:$CM$303) -> 0 | D16: =IFERROR(C16/$B$4,0) -> 0 | E16: =RANK(F16,$F$9:$F$20) -> 8 | F16: =B16+C16/1000+(12-7)/100000 -> 5e-05
A17: إيجاد فني موثوق للتركيب | B17: =COUNTIF(الإجابات!$CN$4:$CN$303,1)*3+COUNTIF(الإجابات!$CN$4:$CN$303,2)*2+COUNTIF(الإجابات!$CN$4:$CN$303,3) -> 0 | C17: =COUNT(الإجابات!$CN$4:$CN$303) -> 0 | D17: =IFERROR(C17/$B$4,0) -> 0 | E17: =RANK(F17,$F$9:$F$20) -> 9 | F17: =B17+C17/1000+(12-8)/100000 -> 4e-05
A18: المنافسة بين المحلات | B18: =COUNTIF(الإجابات!$CO$4:$CO$303,1)*3+COUNTIF(الإجابات!$CO$4:$CO$303,2)*2+COUNTIF(الإجابات!$CO$4:$CO$303,3) -> 0 | C18: =COUNT(الإجابات!$CO$4:$CO$303) -> 0 | D18: =IFERROR(C18/$B$4,0) -> 0 | E18: =RANK(F18,$F$9:$F$20) -> 10 | F18: =B18+C18/1000+(12-9)/100000 -> 3e-05
A19: الحصول على البضاعة من الموردين | B19: =COUNTIF(الإجابات!$CP$4:$CP$303,1)*3+COUNTIF(الإجابات!$CP$4:$CP$303,2)*2+COUNTIF(الإجابات!$CP$4:$CP$303,3) -> 0 | C19: =COUNT(الإجابات!$CP$4:$CP$303) -> 0 | D19: =IFERROR(C19/$B$4,0) -> 0 | E19: =RANK(F19,$F$9:$F$20) -> 11 | F19: =B19+C19/1000+(12-10)/100000 -> 2e-05
A20: أخرى | B20: =COUNTIF(الإجابات!$CQ$4:$CQ$303,1)*3+COUNTIF(الإجابات!$CQ$4:$CQ$303,2)*2+COUNTIF(الإجابات!$CQ$4:$CQ$303,3) -> 0 | C20: =COUNT(الإجابات!$CQ$4:$CQ$303) -> 0 | D20: =IFERROR(C20/$B$4,0) -> 0 | E20: =RANK(F20,$F$9:$F$20) -> 12 | F20: =B20+C20/1000+(12-11)/100000 -> 1e-05
A22: أعلى 5 مشاكل | B22: النقاط
A23: =IF(INDEX($B$9:$B$20,MATCH(1,$E$9:$E$20,0))=0,"—",1&". "&INDEX($A$9:$A$20,MATCH(1,$E$9:$E$20,0))) -> — | B23: =INDEX($B$9:$B$20,MATCH(1,$E$9:$E$20,0)) -> 0
A24: =IF(INDEX($B$9:$B$20,MATCH(2,$E$9:$E$20,0))=0,"—",2&". "&INDEX($A$9:$A$20,MATCH(2,$E$9:$E$20,0))) -> — | B24: =INDEX($B$9:$B$20,MATCH(2,$E$9:$E$20,0)) -> 0
A25: =IF(INDEX($B$9:$B$20,MATCH(3,$E$9:$E$20,0))=0,"—",3&". "&INDEX($A$9:$A$20,MATCH(3,$E$9:$E$20,0))) -> — | B25: =INDEX($B$9:$B$20,MATCH(3,$E$9:$E$20,0)) -> 0
A26: =IF(INDEX($B$9:$B$20,MATCH(4,$E$9:$E$20,0))=0,"—",4&". "&INDEX($A$9:$A$20,MATCH(4,$E$9:$E$20,0))) -> — | B26: =INDEX($B$9:$B$20,MATCH(4,$E$9:$E$20,0)) -> 0
A27: =IF(INDEX($B$9:$B$20,MATCH(5,$E$9:$E$20,0))=0,"—",5&". "&INDEX($A$9:$A$20,MATCH(5,$E$9:$E$20,0))) -> — | B27: =INDEX($B$9:$B$20,MATCH(5,$E$9:$E$20,0)) -> 0
A28: س41. طريقة الدفع المفضلة
A29: الخيار | B29: العدد | C29: النسبة
A30: نسبة صغيرة من كل بيعة تتم عبر التطبيق | B30: =COUNTIF(الإجابات!$DM$4:$DM$303,"نسبة صغيرة من كل بيعة تتم عبر التطبيق") -> 0 | C30: =IFERROR(B30/$B$34,0) -> 0
A31: اشتراك شهري ثابت | B31: =COUNTIF(الإجابات!$DM$4:$DM$303,"اشتراك شهري ثابت") -> 0 | C31: =IFERROR(B31/$B$34,0) -> 0
A32: مجاني مع إعلانات | B32: =COUNTIF(الإجابات!$DM$4:$DM$303,"مجاني مع إعلانات") -> 0 | C32: =IFERROR(B32/$B$34,0) -> 0
A33: لا أدفع إطلاقًا | B33: =COUNTIF(الإجابات!$DM$4:$DM$303,"لا أدفع إطلاقًا") -> 0 | C33: =IFERROR(B33/$B$34,0) -> 0
A34: عدد من أجاب | B34: =COUNTA(الإجابات!$DM$4:$DM$303) -> 0
A35: الأكثر تفضيلًا | B35: =IF(MAX(B30:B33)=0,"—",INDEX(A30:A33,MATCH(MAX(B30:B33),B30:B33,0))) -> —
A36: س42. أعلى عمولة يقبلها
A37: الخيار | B37: العدد | C37: النسبة
A38: نسبة 1–2% | B38: =COUNTIF(الإجابات!$DN$4:$DN$303,"نسبة 1–2%") -> 0 | C38: =IFERROR(B38/$B$43,0) -> 0
A39: نسبة 3% | B39: =COUNTIF(الإجابات!$DN$4:$DN$303,"نسبة 3%") -> 0 | C39: =IFERROR(B39/$B$43,0) -> 0
A40: نسبة 5% | B40: =COUNTIF(الإجابات!$DN$4:$DN$303,"نسبة 5%") -> 0 | C40: =IFERROR(B40/$B$43,0) -> 0
A41: أكثر من 5% | B41: =COUNTIF(الإجابات!$DN$4:$DN$303,"أكثر من 5%") -> 0 | C41: =IFERROR(B41/$B$43,0) -> 0
...

Sheet القوائم
A1: نعم/لا | B1: س1 | C1: س2 | D1: س3 | E1: س7 | F1: س8 | G1: س11 | H1: س12 | I1: س13 | J1: س14 | K1: س15 | L1: س16 | M1: س17 | N1: س18 | O1: س19 | P1: س20 | Q1: س23 | R1: س24 | S1: س25 | T1: س26 | U1: س28 | V1: س29 | W1: س31 | X1: س33 | Y1: س39 | Z1: س41 | AA1: س42 | AB1: س44 | AC1: س45 | AD1: حجم المحل | AE1: تنظيم المحل والبضاعة | AF1: راحة صاحب المحل مع الهاتف | AG1: مكانته وتأثيره | AH1: اهتمامه الحقيقي بالفكرة | AI1: كان مستعجلًا أثناء المقابلة
A2: نعم | B2: أقل من سنة | C2: صاحب المحل | D2: 1 | E2: أقل من 100 | F2: أقل من 5 | G2: نادرًا | H2: أعتذر ويذهب الزبون | I2: يحضر القطعة القديمة | J2: تقريبًا لا شيء | K2: نعم، بنفسي أو بموظف | L2: يوميًا | M2: من ذاكرتي | N2: كثيرًا | O2: حسب سعر الشراء + ربح ثابت | P2: لا أمانع | Q2: لا أبيع بالدين | R2: دائمًا | S2: فني يعمل معي | T2: كثيرًا | U2: هاتف ذكي أندرويد | V2: جيدة أغلب الوقت | W2: نعم وأستخدمه | X2: أنا بنفسي | Y2: مهمة جدًا | Z2: نسبة صغيرة من كل بيعة تتم عبر التطبيق | AA2: نسبة 1–2% | AB2: نعم بالتأكيد | AC2: نعم | AD2: صغير | AE2: منظم | AF2: عالية | AG2: مؤثر | AH2: عالٍ | AI2: نعم
A3: لا | B3: 1–5 سنوات | C3: شريك | D3: 2 | E3: 100–500 | F3: 5–15 | G3: مرة أو مرتين في اليوم | H3: أدلّه على محل آخر | I3: يرسل صورة | J3: أقل من ساعة | K3: نعم، عبر ركشة أو مواصلات | L3: أسبوعيًا | M3: دفتر | N3: أحيانًا | O3: حسب أسعار الجيران | P3: أمانع قليلًا | Q3: أبيع ولا مشاكل | R3: أحيانًا | S3: فني في الشارع أتعامل معه | T3: أحيانًا | U3: آيفون | V3: متقطعة | W3: عندي لكن لا أستخدمه | X3: ابني أو قريبي | Y3: مهمة | Z3: اشتراك شهري ثابت | AA3: نسبة 3% | AB3: ربما، أريد أن أرى أولًا | AC3: لا | AD3: متوسط | AE3: متوسط | AF3: متوسطة | AG3: عادي | AH3: متوسط | AI3: لا
B4: 6–10 سنوات | C4: ابن أو قريب صاحب المحل | D4: 3–5 | E4: 500–2,000 | F4: 16–30 | G4: عدة مرات في اليوم | H4: أجلبها من محل آخر وأبيعها له | I4: يصفها بالكلام | J4: 1–2 ساعة | K4: نادرًا | L4: شهريًا | M4: برنامج أو إكسل على الكمبيوتر | N4: نادرًا | O4: حسب سعر الصرف (الدولار) | P4: أمانع جدًا | Q4: أبيع وأجد صعوبة في التحصيل | R4: نادرًا | S4: الزبون يتصرف بنفسه | T4: نادرًا | U4: هاتف عادي (غير ذكي) | V4: ضعيفة جدًا | W4: لا | X4: موظف في المحل | Y4: غير مهمة | Z4: مجاني مع إعلانات | AA4: نسبة 5% | AB4: لا | AD4: كبير | AE4: غير منظم | AF4: ضعيفة | AH4: ضعيف
B5: أكثر من 10 سنوات | C5: موظف | D5: أكثر من 5 | E5: أكثر من 2,000 | F5: أكثر من 30 | G5: أغلب الزبائن | H5: أطلبها وأقول له يرجع بعدين | I5: نادرًا ما يحدث | J5: أكثر من ساعتين | K5: لا | L5: نادرًا | M5: تطبيق على الهاتف | N5: أبدًا | O5: حسب الزبون | S5: لا أعرف | Z5: لا أدفع إطلاقًا | AA5: أكثر من 5%
E6: لا أعرف | AA6: لا أقبل نسبة
